Workbook

Sheet Лист1
A1: ID_МАИС | B1: Наименование услуги | C1: Федеральная/ Региональная/ муниципальная | D1: Гражданство | E1: Тип регистрации в Кабардино-Балкарской Республике | F1: Получено удостоверение Ветерана боевых действий | G1: Получена справка об участии в СВО | H1: Есть инвалидность | I1: Требуется комплексное сопровождение филиала Фонда "Защитники Отечества" | J1: Плачу налоги (транспортный, земельный налог, налог на имущество физ. лиц) | K1: наличие несовершеннолетних детей | L1: имею право на санаторно-курортное лечение | M1: Получаю ежемесячную денежную выплату | N1: Необходимо подать заявление о банкротстве | O1: Хочу газификацировать жилое помещение (недвижимость), которое не подключено централизованно | P1: Семья является многодетной | Q1: Есть дети, обучающиеся в образовательных организациях | R1: Справка МСЭ (медико-социальной экспертизы) | S1: ИПРА (индивидуальная программа реабилитации) | T1: Медицинское заключение для получения технических средств реабилитации | U1: Справка о ранении | V1: наличие имущества на правах аренды, собственности | W1: Кем вы являетесь для участника СВО? | X1: Размер дохода менее 1 МРОТ?
B2: Тип поля: | D2: РФ Иное | E2: Постоянная Временная Без регистрации | F2: Да/Нет | G2: Да/Нет | H2: Да/Нет | I2: Да/Нет | J2: Да/Нет | K2: Да/Нет | L2: Да/Нет | M2: Да/Нет | N2: Да/Нет | O2: Да/Нет | P2: Да/Нет | Q2: Да/Нет | R2: Да/Нет | S2: Да/Нет | T2: Да/Нет | U2: Да/Нет | V2: Да/Нет | W2: Родитель, супруг, ребенок | X2: Да/Нет
A3: 1 | B3: Взимание и использование родительской платы за присмотр и уход за воспитанником в образовательных учреждениях , реализующих основную образовательную программу дошкольного образования | C3: М | D3: РФ | E3: Постоянная Временная | F3: Да | G3: Да | H3: Да | K3: Да | P3: Да | R3: Да
A4: 2 | B4: Прием заявлений постановка на учет и зачисление детей в образовательные организации реализующие основную общеобразовательную программу дошкольного образования в образовательных организациях | C4: М | D4: РФ | E4: Постоянная Временная | F4: Да | G4: Да | H4: Да | K4: Да | P4: Да | R4: Да
A5: 3 | B5: Предоставление отсрочки уплаты арендной платы по договорам аренды муниципального имущества в связи с частичной мобилизацией | C5: М | D5: РФ | E5: Постоянная Временная | F5: Да | G5: Да | V5: Да
A6: 4 | B6: Обеспечение бесплатным питанием обучающихся муниципальных казенных общеобразовательных учреждений муниципальных районов КБР | C6: М | D6: РФ | E6: Постоянная Временная | F6: Да | G6: Да | K6: Да | P6: Да | Q6: Да
A7: 5 | B7: Прием на обучение по образовательным программам начального общего основного общего и среднего общего образования в учреждения муниципальных районов КБР | C7: М | D7: РФ | E7: Постоянная Временная | F7: Да | G7: Да | K7: Да | P7: Да | Q7: Да
A8: 6 | B8: О бесплатном предоставлении в собственность отдельным категориям граждан земельных участков для индивидуального жилищного строительства на территории Кабардино-Балкарской Республики | C8: М | D8: РФ | E8: Постоянная | F8: Да | G8: Да
A9: 7 | B9: Освобождение от начисления пеней в случае несвоевременного и (или) неполного внесения гражданами Российской Федерации заключившими контракт о прохождении военной службы в связи с призывом на военную службу по мобилизации в Вооруженные Силы Российской Федерации и члены их семей платы за жилое помещение и коммунальные услуги взноса на капитальный ремонт общего имущества в многоквартирном доме установленных жилищным законодательством Российской Федерации | C9: М | D9: РФ Иное | E9: Постоянная Временная | F9: Да | G9: Да | V9: да
A10: 8 | B10: Предоставление семьям участников специальной военной операции права бесплатного посещения детьми занятий по дополнительным общеобразовательным программам в региональных и муниципальных организациях (кружки, секции и иные подобные занятия) (в том числе в случае гибели (смерти) участников специальной военной операции) | C10: М | D10: РФ Иное | E10: Постоянная Временная | G10: Да | K10: Да | P10: Да | Q10: Да | W10: Родитель, супруг, ребенок
A11: 9 | B11: Организации оздоровления отдыха и занятости детей в летний период | C11: М | D11: РФ | E11: Постоянная | F11: Да | G11: Да | K11: Да | L11: Да | P11: Да | W11: Да
A12: 10 | B12: Первоочередное право на приобретение садовых земельных участков или огородных земельных участков | C12: М | D12: РФ | E12: Постоянная | F12: Да | G12: Да | V12: Да
A13: 11 | B13: Освобождение от уплаты услуг по водоснабжению и водоотведению | C13: М | D13: РФ | E13: Постоянная Временная | F13: Да | G13: Да | V13: Да
A14: 12 | B14: Предоставление возможности расторжения договоров аренды без применения штрафных санкций | C14: М | D14: РФ | E14: Постоянная Временная | F14: Да | G14: Да | V14: Да
A15: 13 | B15: Зачисление в первоочередном порядке в образовательную организацию на обучение по образовательным программам среднего профессионального образования | C15: Р | D15: РФ Иное | E15: Постоянная Временная | F15: Да | G15: Да | H15: Да | K15: Да | P15: Да | Q15: Да | W15: ребенок
A16: 14 | B16: Единовременная материальная помощь членам семей погибших (умерших) военнослужащих, лиц, проходивших службу в войсках национальной гвардии Российской Федерации | C16: Р | D16: РФ | E16: Постоянная Временная Без регистрации | F16: Да | G16: Да | K16: Да | W16: Родитель, супруг, ребенок
A17: 15 | B17: Организация на территории Кабардино-Балкарской Республики санаторно-курортного лечения | C17: Р | D17: РФ Иное | E17: Постоянная Временная | F17: Да | G17: Да | H17: Да | I17: Да | L17: Да | M17: Да | R17: Да | U17: Да
A18: 16 | B18: Единовременная материальная помощь военнослужащим, лицам, проходящим службу в войсках Росгвардии: при получении легкого увечья (ранения, травмы, контузии) - в размере 100000,0 рублей; при получении тяжкого увечья (ранения, травмы, контузии) - в размере 300000,0 рублей; при получении увечья (ранения, травмы, контузии), не входящего в перечень увечий (ранений, травм, контузий), - в размере 100000 рублей. | C18: Р | D18: РФ Иное | E18: Постоянная Временная | F18: Да | G18: Да | U18: Да
A19: 17 | B19: Единовременная материальная помощь лицам, поступившим в созданные по решению органов государственной власти Российской Федерации добровольческие формирования); при получении в результате легкого вреда здоровью - в размере 100000 рублей; при получении в результате вреда здоровью средней тяжести - в размере 200000 рублей; при получении в результате тяжкого вреда здоровью - в размере 300000 рублей | C19: Р | D19: РФ Иное | E19: Постоянная Временная | F19: Да | G19: Да | U19: Да
A20: 18 | B20: Единовременная материальная помощь сотрудникам расположенных на территории КБР следственных органов СК РФ (кроме военнослужащих), сотрудников, назначенных в порядке перевода из указанных органов в следственные органы СК РФ по Донецкой Народной Республике, Луганской Народной Республике, Запорожской области или Херсонской области (кроме военнослужащих), получивших на территориях Украины, Донецкой Народной Республики, Луганской Народной Республики, Запорожской области, Херсонской области при получении в результате легкого вреда здоровью - в размере 100000 рублей; при получении в результате вреда здоровью средней тяжести - в размере 200000 рублей; при получении в результате тяжкого вреда здоровью - в размере 300000 рублей | C20: Р | D20: РФ Иное | E20: Постоянная Временная | F20: Да | G20: Да | U20: Да
A21: 19 | B21: Оказание медицинской помощи в медицинских организациях во внеочередном порядке участникам специальной военной операции | C21: Р | D21: РФ | E21: Постоянная Временная Без регистрации | F21: Да | G21: Да | H21: Да | I21: Да
A22: 20 | B22: Обеспечение бесплатного посещения культурно-массовых мероприятий на территории Кабардино-Балкарской Республики для лиц участников СВО и членам семей принимающих (принимавших) участие в специальной военной операции | C22: Р | D22: РФ Иное | E22: Постоянная Временная Без регистрации | F22: Да | G22: Да | K22: Да | W22: Ребенок
A23: 21 | B23: Оказание государственной социальной помощи на основании социального контракта | C23: Р | D23: РФ Иное | E23: Постоянная Временная | F23: Да | G23: Да | H23: Да | K23: Да | M23: Да | P23: Да | R23: Да | X23: Да
A24: 22 | B24: Предоставление в первоочередном порядке путевок на отдых и оздоровление детям участников СВО, внеочередное направление детей на медико-социальную реабилитацию в ГКУ "Базовый республиканский детский социально-реабилитационный центр "Радуга". | C24: Р | D24: РФ Иное | E24: Постоянная Временная | F24: Да | G24: Да | K24: Да | L24: Да | P24: Да | W24: Ребенок
A25: 23 | B25: Предоставление в прокат технических средств реабилитации для членов семей граждан, участвующих в специальной военной операции | C25: Р | D25: РФ Иное | E25: Постоянная Временная | F25: Да | G25: Да | H25: Да | I25: Да | R25: Да | T25: Да
A26: 24 | B26: Организация профессионального обучения и дополнительного профессионального образования, содействие в поиске подходящей работы | C26: Р | D26: РФ | E26: Постоянная Временная | F26: Да | G26: Да | H26: Да | I26: Да
A27: 25 | B27: Оказание психологической помощи | C27: Р | D27: РФ | E27: Постоянная Временная Без регистрации | F27: Да | G27: Да | H27: Да | I27: Да
A28: 26 | B28: Предоставление участникам специальной военной операции и членам их семей права бесплатного посещения спортивных объектов | C28: Р | D28: РФ Иное | E28: Постоянная Временная Без регистрации | F28: Да | G28: Да | K28: Да | W28: Родитель, супруг, ребенок
A29: 27 | B29: Признание гражданина нуждающимся в социальном обслуживании | C29: Р | D29: РФ Иное | E29: Постоянная Временная | F29: Да | G29: Да | H29: Да | I29: Да | M29: Да | R29: Да
A30: 28 | B30: Обеспечение бесплатного посещения культурно-массовых мероприятий, кружков и секций | C30: Р | D30: РФ Иное | E30: Постоянная Временная Без регистрации | F30: Да | G30: Да | K30: Да
A31: 29 | B31: Компенсация расходов на оплату компенсацию расходов на оплату жилищно-коммунальных услуг участнику СВО являющегося ветераном боевых действий | C31: Р | D31: РФ Иное | E31: Постоянная Временная | F31: Да | G31: Да | H31: Да | K31: Да | M31: Да | P31: Да | R31: Да
A32: 30 | B32: Внеочередное обслуживание в МФЦ | C32: Р | D32: РФ Иное | E32: Постоянная Временная Без регистрации | F32: Да | G32: Да | H32: Да | K32: Да | W32: Родитель, супруг, ребенок
A33: 31 | B33: Социальная поддержка детей-сирот и детей, оставшихся без попечения родителей, в КБР | C33: Р | D33: РФ | E33: Постоянная Временная | G33: Да | K33: Да | Q33: Да | W33: Ребенок
A34: 32 | B34: Ежемесячная денежная выплата в размере 25 000 рублей военнослужащим призванным военным комиссариатом Кабардино-Балкарской Республики на военную службу в соответствии с Указом Президента Российской Федерации от 21 сентября 2022 г. № 647 "Об объявлении частичной мобилизации в Российской Федерации" в период прохождения ими военной службы | C34: Р | D34: РФ | E34: Постоянная Временная Без регистрации | G34: Да
A35: 33 | B35: Предоставление субсидии на оплату жилого помещения и коммунальных услуг | C35: Р | D35: РФ | E35: Постоянная | F35: Да | G35: Да | H35: Да | K35: Да | M35: Да | P35: Да | Q35: Да | R35: Да | X35: Да
A36: 34 | B36: Академическое право на переход лиц, обучающихся по образовательным программам среднего профессионального и высшего образования, с платного обучения на бесплатное | C36: Ф | D36: РФ | E36: Постоянная Временная Без регистрации | G36: Да | K36: Да | Q36: Да | W36: Супруг, ребенок
A37: 35 | B37: Право на прием на обучение по программам бакалавриата и программам специалитета в образовательные организации высшего образования за счет бюджетных ассигнований федерального бюджета, бюджетов субъектов Российской Федерации и местных бюджетов в пределах отдельной квоты | C37: Ф | D37: РФ | E37: Постоянная Временная Без регистрации | G37: Да | K37: Да | Q37: Да | W37: Супруг, ребенок
A38: 36 | B38: Право на прием на обучение на подготовительные отделения в федеральные государственные образовательные организации высшего образования за счет бюджетных ассигнований федерального бюджета, бюджетов субъектов Российской Федерации и местных бюджетов в пределах отдельной квоты | C38: Ф | D38: РФ | E38: Постоянная Временная Без регистрации | G38: Да | K38: Да | Q38: Да | W38: Супруг, ребенок
A39: 37 | B39: Предоставление набора социальных услуг | C39: Ф | D39: РФ, иное | E39: Постоянная Временная Без регистрации | F39: Да | H39: Да | M39: Да | R39: Да
A40: 38 | B40: Ежемесячная денежная выплата ветеранам боевых действий | C40: Ф | D40: РФ, иное | E40: Постоянная Временная Без регистрации | F40: Да | H40: Да | R40: Да
...

Sheet Лист2
F1: Получено удостоверение Ветерана боевых действий | G1: Получена справка об участии в СВО | H1: Есть инвалидность | I1: Требуется комплексное сопровождение филиала Фонда "Защитники Отечества" | J1: Плачу налоги (транспортный, земельный налог, налог на имущество физ. лиц) | K1: Наличие несовершеннолетних детей | L1: Имею право на санаторно-курортное лечение | M1: Получаю ежемесячную денежную выплату | N1: Необходимо подать заявление о банкротстве | O1: Хочу газификацировать жилое помещение (недвижимость), которое не подключено централизованно | P1: Семья является многодетной | Q1: Есть дети, обучающиеся в образовательных организациях | R1: Справка МСЭ (медико-социальной экспертизы) | S1: ИПРА (индивидуальная программа реабилитации) | T1: Медицинское заключение для получения технических средств реабилитации | U1: Справка о ранении | V1: Наличие имущества на правах аренды, собственности | W1: Кем вы являетесь для участника СВО? | X1: Размер дохода менее 1 МРОТ?
F5: В строке 2 под каждым вопросом в случае положительного ответа вписать "да". Если заявитель не подхоит под параметр то оставить поле пустым

Sheet Лист3
B1: Перечень услуг доступных к получению участникам СВО и членам их семей
A2: №
A3: =IF(B3<>"",MAX($A$2:A2)+1,"") | B3: =IFERROR(INDEX($C$3:$C$61,MATCH(ROW(A1),$D$3:$D$61,0)),"") | C3: {=IF(SUMPRODUCT((Лист1!F3:X3="Да")*(Лист2!F$2:X$2="Да"))>0,Лист1!B3,"")} | D3: =IF(C3<>"",MAX($D$2:D2)+1,"")
A4: =IF(B4<>"",MAX($A$2:A3)+1,"") | B4: =IFERROR(INDEX($C$3:$C$61,MATCH(ROW(A2),$D$3:$D$61,0)),"") | C4: =IF(SUMPRODUCT((Лист1!F4:X4="Да")*(Лист2!F$2:X$2="Да"))>0,Лист1!B4,"") | D4: =IF(C4<>"",MAX($D$2:D3)+1,"")
A5: =IF(B5<>"",MAX($A$2:A4)+1,"") | B5: =IFERROR(INDEX($C$3:$C$61,MATCH(ROW(A3),$D$3:$D$61,0)),"") | C5: =IF(SUMPRODUCT((Лист1!F5:X5="Да")*(Лист2!F$2:X$2="Да"))>0,Лист1!B5,"") | D5: =IF(C5<>"",MAX($D$2:D4)+1,"")
A6: =IF(B6<>"",MAX($A$2:A5)+1,"") | B6: =IFERROR(INDEX($C$3:$C$61,MATCH(ROW(A4),$D$3:$D$61,0)),"") | C6: =IF(SUMPRODUCT((Лист1!F6:X6="Да")*(Лист2!F$2:X$2="Да"))>0,Лист1!B6,"") | D6: =IF(C6<>"",MAX($D$2:D5)+1,"")
A7: =IF(B7<>"",MAX($A$2:A6)+1,"") | B7: =IFERROR(INDEX($C$3:$C$61,MATCH(ROW(A5),$D$3:$D$61,0)),"") | C7: =IF(SUMPRODUCT((Лист1!F7:X7="Да")*(Лист2!F$2:X$2="Да"))>0,Лист1!B7,"") | D7: =IF(C7<>"",MAX($D$2:D6)+1,"")
A8: =IF(B8<>"",MAX($A$2:A7)+1,"") | B8: =IFERROR(INDEX($C$3:$C$61,MATCH(ROW(A6),$D$3:$D$61,0)),"") | C8: =IF(SUMPRODUCT((Лист1!F8:X8="Да")*(Лист2!F$2:X$2="Да"))>0,Лист1!B8,"") | D8: =IF(C8<>"",MAX($D$2:D7)+1,"")
A9: =IF(B9<>"",MAX($A$2:A8)+1,"") | B9: =IFERROR(INDEX($C$3:$C$61,MATCH(ROW(A7),$D$3:$D$61,0)),"") | C9: =IF(SUMPRODUCT((Лист1!F9:X9="Да")*(Лист2!F$2:X$2="Да"))>0,Лист1!B9,"") | D9: =IF(C9<>"",MAX($D$2:D8)+1,"")
A10: =IF(B10<>"",MAX($A$2:A9)+1,"") | B10: =IFERROR(INDEX($C$3:$C$61,MATCH(ROW(A8),$D$3:$D$61,0)),"") | C10: =IF(SUMPRODUCT((Лист1!F10:X10="Да")*(Лист2!F$2:X$2="Да"))>0,Лист1!B10,"") | D10: =IF(C10<>"",MAX($D$2:D9)+1,"")
A11: =IF(B11<>"",MAX($A$2:A10)+1,"") | B11: =IFERROR(INDEX($C$3:$C$61,MATCH(ROW(A9),$D$3:$D$61,0)),"") | C11: =IF(SUMPRODUCT((Лист1!F11:X11="Да")*(Лист2!F$2:X$2="Да"))>0,Лист1!B11,"") | D11: =IF(C11<>"",MAX($D$2:D10)+1,"")
A12: =IF(B12<>"",MAX($A$2:A11)+1,"") | B12: =IFERROR(INDEX($C$3:$C$61,MATCH(ROW(A10),$D$3:$D$61,0)),"") | C12: =IF(SUMPRODUCT((Лист1!F12:X12="Да")*(Лист2!F$2:X$2="Да"))>0,Лист1!B12,"") | D12: =IF(C12<>"",MAX($D$2:D11)+1,"")
A13: =IF(B13<>"",MAX($A$2:A12)+1,"") | B13: =IFERROR(INDEX($C$3:$C$61,MATCH(ROW(A11),$D$3:$D$61,0)),"") | C13: =IF(SUMPRODUCT((Лист1!F13:X13="Да")*(Лист2!F$2:X$2="Да"))>0,Лист1!B13,"") | D13: =IF(C13<>"",MAX($D$2:D12)+1,"")
A14: =IF(B14<>"",MAX($A$2:A13)+1,"") | B14: =IFERROR(INDEX($C$3:$C$61,MATCH(ROW(A12),$D$3:$D$61,0)),"") | C14: =IF(SUMPRODUCT((Лист1!F14:X14="Да")*(Лист2!F$2:X$2="Да"))>0,Лист1!B14,"") | D14: =IF(C14<>"",MAX($D$2:D13)+1,"")
A15: =IF(B15<>"",MAX($A$2:A14)+1,"") | B15: =IFERROR(INDEX($C$3:$C$61,MATCH(ROW(A13),$D$3:$D$61,0)),"") | C15: =IF(SUMPRODUCT((Лист1!F15:X15="Да")*(Лист2!F$2:X$2="Да"))>0,Лист1!B15,"") | D15: =IF(C15<>"",MAX($D$2:D14)+1,"")
... A61: =IF(B61<>"",MAX($A$2:A60)+1,"") | B61: =IFERROR(INDEX($C$3:$C$61,MATCH(ROW(A59),$D$3:$D$61,0)),"") | C61: =IF(SUMPRODUCT((Лист1!F61:X61="Да")*(Лист2!F$2:X$2="Да"))>0,Лист1!B61,"") | D61: =IF(C61<>"",MAX($D$2:D60)+1,"")
A62: =IF(B62<>"",MAX($A$2:A61)+1,"") | B62: =IFERROR(INDEX($C$3:$C$61,MATCH(ROW(A60),$D$3:$D$61,0)),"") | D62: =IF(C62<>"",MAX($D$2:D61)+1,"")
A63: =IF(B63<>"",MAX($A$2:A62)+1,"") | B63: =IFERROR(INDEX($C$3:$C$61,MATCH(ROW(A61),$D$3:$D$61,0)),"") | D63: =IF(C63<>"",MAX($D$2:D62)+1,"")
